<?xml version="1.0"?>
<robot name="robot">
    <!--Gazebo Color Tags-->
    <gazebo reference="base_link">
        <material>Gazebo/Black</material>
    </gazebo>
    <gazebo reference="base_footprint">
        <material>Gazebo/Black</material>
    </gazebo>
    <gazebo reference="front_caster">
        <material>Gazebo/Grey</material>
    </gazebo>
    <gazebo reference="back_caster">
        <material>Gazebo/Grey</material>
    </gazebo>
    <gazebo reference="left_wheel">
        <material>Gazebo/Red</material>
    </gazebo>
    <gazebo reference="right_wheel">
        <material>Gazebo/Red</material>
    </gazebo>

	<!-- Base Footprint -->
	<link name="base_footprint">
		<inertial>
			<mass value="21" />
			<origin xyz="0 0 0" rpy="0 0 0" />
			<inertia ixx="0.0001" ixy="0" ixz="0" iyy="0.0001" iyz="0" izz="0.0001" />
		</inertial>
		<visual>
			<geometry>
				<cylinder length="0.0125" radius="0.25"/>
			</geometry>
            <material name="Blue">
                <color rgba="0 0 1 0.25" />
            </material>
		</visual>
		<collision>
			<geometry>
				<cylinder length="0.0125" radius="0.25"/>
			</geometry>
		</collision>
	</link>

	<!-- Base Link -->
	<link name="base_link">
		<!-- <inertial>
			<mass value="5" />
			<origin xyz="0 0 0.3" rpy="0 0 0" />
			<inertia ixx="0.0001" ixy="0" ixz="0" iyy="0.0001" iyz="0" izz="0.0001" />
		</inertial> -->
		<visual>
			<geometry>
				<cylinder length="0.3" radius="0.25"/>
			</geometry>
            <material name="Blue">
                <color rgba="0 0 1 0.25" />
            </material>
		</visual>
		<collision>
			<geometry>
				<cylinder length="0.3" radius="0.25"/>
			</geometry>
		</collision>
	</link>

	<!-- Right Wheel -->
	<link name="right_wheel">
        <inertial>
            <mass value="1" />
            <origin xyz="0 0 0" rpy="0 0 0" />
            <inertia ixx="0.0001" ixy="0" ixz="0" iyy="0.0001" iyz="0" izz="0.0001"/>
        </inertial>
		<visual>
			<origin rpy="-1.5708 0 0" xyz="0 0 0" />
			<geometry>
				<cylinder length="0.05" radius="0.05"/>
			</geometry>
			<material name="Red">
     			<color rgba="1 0 0 1" />
     		</material>
		</visual>
		<collision>
			<origin rpy="-1.5708 0 0" xyz="0 0 0" />
			<geometry>
				<cylinder length="0.05" radius="0.05"/>
			</geometry>
		</collision>
	</link>

	<!-- Left Wheel -->	
	<link name="left_wheel">
        <inertial>
            <mass value="1" />
            <origin xyz="0 0 0" rpy="0 0 0" />
            <inertia ixx="0.0001" ixy="0" ixz="0" iyy="0.0001" iyz="0" izz="0.0001"/>
        </inertial>
		<visual>
			<origin rpy="1.5708 0 0" xyz="0 0 0" />
			<geometry>
				<cylinder length="0.05" radius="0.05"/>
			</geometry>
			<material name="Red">
     			<color rgba="1 0 0 1" />
     		</material>
		</visual>
		<collision>
			<origin rpy="1.5708 0 0" xyz="0 0 0" />
			<geometry>
				<cylinder length="0.05" radius="0.05"/>
			</geometry>
		</collision>
	</link>

	<!-- Front Caster -->
	<link name="front_caster">
        <inertial>
			<mass value="1" />
			<origin xyz="0 0 0" rpy="0 0 0" />
			<inertia ixx="0.0001" ixy="0" ixz="0" iyy="0.0001" iyz="0" izz="0.0001"/>
		</inertial>

		<!--CasterWheel-Support-->
		<visual>
			 <origin rpy="0 0 0" xyz="0 0 0" />
			<geometry>
				<sphere radius="0.04"/>
			</geometry>
			<material name="Blue">
     			        <color rgba="0 0 1 1" />
     			</material>
		</visual>
		<collision>
			 <origin rpy="0 0 0" xyz="0 0 0" />
			<geometry>
				<sphere radius="0.04"/>
			</geometry>
		</collision>

		<!--CasterWheel-->
		<visual>
			<origin rpy="0 0 0" xyz="0 0 -0.03" />
			<geometry>
				<sphere radius="0.02"/>
			</geometry>
			<material name="Grey">
     			        <color rgba="0.6 0.6 0.6 1" />
     			</material>
		</visual>
		<collision>
			<origin rpy="0 0 0" xyz="0 0 -0.03" />
			<geometry>
				<sphere radius="0.02"/>
			</geometry>
		</collision>
	</link>

	<!-- Back Caster -->
	<link name="back_caster">
        <inertial>
			<mass value="1" />
			<origin xyz="0 0 0" rpy="0 0 0" />
			<inertia ixx="0.0001" ixy="0" ixz="0" iyy="0.0001" iyz="0" izz="0.0001"/>
		</inertial>

		<!--CasterWheel-Support-->
		<visual>
			<origin xyz="0 0 0" rpy="0 0 0" />
			<geometry>
				<sphere radius="0.04"/>
			</geometry>
			<material name="Blue">
     			        <color rgba="0 0 1 1" />
     			</material>
		</visual>
		<collision>
			<origin xyz="0 0 0" rpy="0 0 0" />
			<geometry>
				<sphere radius="0.04"/>
			</geometry>
		</collision>

		<!--CasterWheel-->
		<visual>
			<origin xyz="0 0 -0.03" rpy="0 0 0" />
			<geometry>
				<sphere radius="0.02"/>
			</geometry>
			<material name="Grey">
     			        <color rgba="0.6 0.6 0.6 1" />
     			</material>
		</visual>
		<collision>
			<origin xyz="0 0 -0.03" rpy="0 0 0" />
			<geometry>
				<sphere radius="0.02"/>
			</geometry>
		</collision>
	</link>

	<!-- Front Laser -->
	<link name="front_laser">   
        <inertial>
            <mass value="1" />
            <origin xyz="0 0 0" rpy="0 0 0" />
            <inertia ixx="0.0001" ixy="0" ixz="0" iyy="0.0001" iyz="0" izz="0.0001"/>
        </inertial>
		<visual>
			<origin xyz="0 0 0" rpy="0 0 0" />
			<geometry>
				<cylinder radius="0.025" length="0.05"/>
			</geometry>
		</visual>
		<collision>
			<origin xyz="0 0 0" rpy="0 0 0" />
			<geometry>
				<cylinder radius="0.025" length="0.05"/>				
			</geometry>
		</collision>
	</link>

	<!-- Joints -->
	<joint name="base_to_base_footprint" type="fixed">
		<parent link="base_link"/>
		<child link="base_footprint"/>
		<origin rpy="0 0 0" xyz="0.0 0.0 -0.15"/>
		<axis xyz="0 0 1"/>
		<joint_properties damping="0.0" friction="0.0" />
	</joint>
	
	<joint name="base_to_right_wheel" type="continuous">
		<parent link="base_link"/>
		<child link="right_wheel"/>
		<origin rpy="0 0 0" xyz="0.0 -0.2 -0.15"/>
		<axis xyz="0 1 0"/>
		<joint_properties damping="0.0" friction="1.0" />
	</joint>
	
	<joint name="base_to_left_wheel" type="continuous">
		<parent link="base_link"/>
		<child link="left_wheel"/>
		<origin rpy="0 0 0" xyz="0.0 0.2 -0.15"/>
		<axis xyz="0 1 0"/>
		<joint_properties damping="0.0" friction="1.0" />
	</joint>

	<joint name="base_to_front_caster" type="fixed">
		<parent link="base_link"/>
		<child link="front_caster"/>
		<origin rpy="0 0 0" xyz="0.1 0.0 -0.15"/>
		<joint_properties damping="0.0" friction="0.0" />
	</joint>

	<joint name="base_to_back_caster" type="fixed">
		<parent link="base_link"/>
		<child link="back_caster"/>
		<origin rpy="0 0 0" xyz="-0.1 0.0 -0.15"/>
		<joint_properties damping="0.0" friction="0.0" />
	</joint>

	<joint name="base_to_front_laser" type="fixed">
		<parent link="base_link"/>
		<child link="front_laser"/>
		<origin rpy="3.14159 0 0" xyz="0.25 0.0 0.075" />
		<joint_properties damping="1.0" friction="1.0" />
	</joint>

    <!--Plugin Diff-Drive-->
    <gazebo>
        <plugin filename="libgazebo_ros_diff_drive.so" name="differential_drive_controller">
            <alwaysOn>true</alwaysOn>
            <updateRate>20</updateRate>
            <leftJoint>base_to_left_wheel</leftJoint>
            <rightJoint>base_to_right_wheel</rightJoint>
            <wheelSeparation>0.3</wheelSeparation>
            <wheelDiameter>0.05</wheelDiameter>
            <torque>10</torque>
            <commandTopic>cmd_vel</commandTopic>
            <odometryTopic>odom</odometryTopic>
            <odometryFrame>odom</odometryFrame>
            <robotBaseFrame>base_link</robotBaseFrame>
        </plugin>    
    </gazebo>

    <!--Plugin Laser-Scan-->
    <gazebo reference="front_laser">
        <sensor type="ray" name="head_hokuyo_sensor">            
            <pose>0 0 0 0 0 0</pose>
            <visualize>true</visualize>
            <update_rate>20</update_rate>
            <ray>
                <scan>
                    <horizontal>
                        <samples>720</samples>
                        <resolution>1</resolution>
                        <min_angle>-1.570796</min_angle>
                        <max_angle>1.570796</max_angle>
                    </horizontal>
                </scan>
                <range>
                    <min>0.30</min>
                    <max>10.0</max>
                    <resolution>0.01</resolution>
                </range>
                <noise>
                    <type>gaussian</type>
                    <mean>0.0</mean>
                    <stddev>0.01</stddev>
                </noise>
            </ray>
            <plugin name="gazebo_ros_head_hokuyo_controller" filename="libgazebo_ros_laser.so">
                <topicName>/scan</topicName>
                <frameName>front_laser</frameName>
            </plugin>
        </sensor>
    </gazebo>

</robot>


